<?xml version="1.0" encoding="utf-8"?>
<!-- This URDF was automatically created by SolidWorks to URDF Exporter! Originally created by Stephen Brawner (brawner@gmail.com)
     Commit Version: 1.6.0-1-g15f4949  Build Version: 1.6.7594.29634
     For more information, please see http://wiki.ros.org/sw_urdf_exporter -->
<robot
  name="car_sample">
  <link
    name="base_footprint_link">

  </link>
  <link
    name="base_link">
    <inertial>
      <origin
        xyz="0.0311047953221113 -3.07460541279329E-06 0.0988375969266445"
        rpy="0 0 0" />
      <mass
        value="93.7017907857414" />
      <inertia
        ixx="2.05155668597246"
        ixy="-0.000190686516366707"
        ixz="-0.0661121479684108"
        iyy="7.87268899063513"
        iyz="2.91444870281255E-05"
        izz="9.28547608261676" />
    </inertial>
    <visual>
      <origin
        xyz="0 0 0"
        rpy="0 0 0" />
      <geometry>
        <mesh
          filename="package://car_sample/meshes/base_link.STL" />
      </geometry>
      <material
        name="">
        <color
          rgba="0.792156862745098 0.819607843137255 0.933333333333333 1" />
      </material>
    </visual>
    <collision>
      <origin
        xyz="0 0 0"
        rpy="0 0 0" />
      <geometry>
        <mesh
          filename="package://car_sample/meshes/base_link.STL" />
      </geometry>
    </collision>
  </link>
  <gazebo reference="base_link">
    <material>Gazebo/White</material>
    <selfCollide>true</selfCollide>
  </gazebo>
  <joint
    name="base_link_joint"
    type="fixed">
    <origin
      xyz="0 0 0.065"
      rpy="0 0 0" />
    <parent
      link="base_footprint_link" />
    <child
      link="base_link" />
    <axis
      xyz="0 0 0" />
  </joint>
  <link
    name="potential_link">
    <inertial>
      <origin
        xyz="-0.429254748784664 -0.00335150189802721 -0.197173586404001"
        rpy="0 0 0" />
      <mass
        value="6.89001102509344" />
      <inertia
        ixx="0.0468982581959443"
        ixy="-0.00452622726574964"
        ixz="0.000258875342996197"
        iyy="0.646005462114825"
        iyz="-1.08164098234481E-05"
        izz="0.676451866172125" />
    </inertial>
    <visual>
      <origin
        xyz="0 0 0"
        rpy="0 0 0" />
      <geometry>
        <mesh
          filename="package://car_sample/meshes/potential_link.STL" />
      </geometry>
      <material
        name="">
        <color
          rgba="0.792156862745098 0.819607843137255 0.933333333333333 1" />
      </material>
    </visual>
    <collision>
      <origin
        xyz="0 0 0"
        rpy="0 0 0" />
      <geometry>
        <mesh
          filename="package://car_sample/meshes/potential_link.STL" />
      </geometry>
    </collision>
  </link>
<gazebo reference="potential_link">
    <material>Gazebo/White</material>
    <selfCollide>true</selfCollide>
  </gazebo>
  <joint
    name="potential_link_joint"
    type="continuous">
    <origin
      xyz="-0.63078 -0.0013586 0.35"
      rpy="0 0 0" />
      <dynamics friction="2"/>
    <parent
      link="base_link" />
    <child
      link="potential_link" />
    <axis
      xyz="0 0 1" />
    <limit
      lower="0"
      upper="0"
      effort="0"
      velocity="0" />
  </joint>
  <link
    name="L_link">
    <inertial>
      <origin
        xyz="0.00019519 -0.024999 2.2204E-16"
        rpy="0 0 0" />
      <mass
        value="6.789" />
      <inertia
        ixx="0.073434"
        ixy="-0.00042251"
        ixz="-1.4684E-17"
        iyy="0.12754"
        iyz="-2.6995E-17"
        izz="0.073431" />
    </inertial>
    <visual>
      <origin
        xyz="0 0 0"
        rpy="0 0 0" />
      <geometry>
        <mesh
          filename="package://car_sample/meshes/L_link.STL" />
      </geometry>
      <material
        name="">
        <color
          rgba="0.79216 0.81961 0.93333 1" />
      </material>
    </visual>
    <collision>
      <origin
        xyz="0 0 0"
        rpy="0 0 0" />
      <geometry>
        <mesh
          filename="package://car_sample/meshes/L_link.STL" />
      </geometry>
    </collision>
  </link>
<gazebo reference="L_link">
    <material>Gazebo/Black</material>
    <selfCollide>true</selfCollide>
  </gazebo>
  <joint
    name="L_joint"
    type="continuous">
    <origin
      xyz="-0.42824 0.41367 -0.265"
      rpy="0 0 0" />
      <dynamics friction="1"/>
    <parent
      link="potential_link" />
    <child
      link="L_link" />
    <axis
      xyz="0 1 0" />
  </joint>
  <link
    name="R_link">
    <inertial>
      <origin
        xyz="-0.00019519 0.024999 1.1102E-16"
        rpy="0 0 0" />
      <mass
        value="6.789" />
      <inertia
        ixx="0.073434"
        ixy="-0.00042251"
        ixz="6.2188E-19"
        iyy="0.12754"
        iyz="-3.8293E-17"
        izz="0.073431" />
    </inertial>
    <visual>
      <origin
        xyz="0 0 0"
        rpy="0 0 0" />
      <geometry>
        <mesh
          filename="package://car_sample/meshes/R_link.STL" />
      </geometry>
      <material
        name="">
        <color
          rgba="0.79216 0.81961 0.93333 1" />
      </material>
    </visual>
    <collision>
      <origin
        xyz="0 0 0"
        rpy="0 0 0" />
      <geometry>
        <mesh
          filename="package://car_sample/meshes/R_link.STL" />
      </geometry>
    </collision>
  </link>
<gazebo reference="R_link">
    <material>Gazebo/Black</material>
    <selfCollide>true</selfCollide>
  </gazebo>
  <joint
    name="R_joint"
    type="continuous">
    <origin
      xyz="-0.41921 -0.42029 -0.26521"
      rpy="0 0 0" />
      <dynamics friction="1"/>
    <parent
      link="potential_link" />
    <child
      link="R_link" />
    <axis
      xyz="0 1 0" />
  </joint>
  <link
    name="LF_link">
    <inertial>
      <origin
        xyz="5.55111512312578E-17 -0.0249999999999999 1.11022302462516E-16"
        rpy="0 0 0" />
      <mass
        value="6.78904509236314" />
      <inertia
        ixx="0.0734309679871221"
        ixy="1.41390840403187E-20"
        ixz="1.32348898008415E-20"
        iyy="0.127548069927643"
        iyz="-2.49612899515053E-20"
        izz="0.0734309679871221" />
    </inertial>
    <visual>
      <origin
        xyz="0 0 0"
        rpy="0 0 0" />
      <geometry>
        <mesh
          filename="package://car_sample/meshes/LF_link.STL" />
      </geometry>
      <material
        name="">
        <color
          rgba="0.792156862745098 0.819607843137255 0.933333333333333 1" />
      </material>
    </visual>
    <collision>
      <origin
        xyz="0 0 0"
        rpy="0 0 0" />
      <geometry>
        <mesh
          filename="package://car_sample/meshes/LF_link.STL" />
      </geometry>
    </collision>
  </link>
<gazebo reference="LF_link">
    <material>Gazebo/Black</material>
    <selfCollide>true</selfCollide>
  </gazebo>
  <joint
    name="LF_joint"
    type="continuous">
    <origin
      xyz="0.29328 0.3725 0.1"
      rpy="0 0 0" />
      <dynamics friction="2"/>
    <parent
      link="base_link" />
    <child
      link="LF_link" />
    <axis
      xyz="0 1 0" />
  </joint>
  <link
    name="LR_link">
    <inertial>
      <origin
        xyz="1.11022302462516E-16 -0.025 2.22044604925031E-16"
        rpy="0 0 0" />
      <mass
        value="6.78904509236314" />
      <inertia
        ixx="0.0734309679871221"
        ixy="-2.05141328700057E-19"
        ixz="-5.29916164366107E-18"
        iyy="0.127548069927643"
        iyz="7.2468785370554E-18"
        izz="0.0734309679871221" />
    </inertial>
    <visual>
      <origin
        xyz="0 0 0"
        rpy="0 0 0" />
      <geometry>
        <mesh
          filename="package://car_sample/meshes/LR_link.STL" />
      </geometry>
      <material
        name="">
        <color
          rgba="0.792156862745098 0.819607843137255 0.933333333333333 1" />
      </material>
    </visual>
    <collision>
      <origin
        xyz="0 0 0"
        rpy="0 0 0" />
      <geometry>
        <mesh
          filename="package://car_sample/meshes/LR_link.STL" />
      </geometry>
    </collision>
  </link>
<gazebo reference="LR_link">
    <material>Gazebo/Black</material>
    <selfCollide>true</selfCollide>
  </gazebo>
  <joint
    name="LR_joint"
    type="continuous">
    <origin
      xyz="-0.20472 0.3725 0.1"
      rpy="0 0 0" />
      <dynamics friction="2"/>
    <parent
      link="base_link" />
    <child
      link="LR_link" />
    <axis
      xyz="0 1 0" />
  </joint>
  <link
    name="RF_link">
    <inertial>
      <origin
        xyz="0 0.025 0"
        rpy="0 0 0" />
      <mass
        value="6.78904509236314" />
      <inertia
        ixx="0.0734309679871221"
        ixy="1.46664827039991E-19"
        ixz="-1.19114008207636E-18"
        iyy="0.127548069927643"
        iyz="-8.89330655265835E-21"
        izz="0.0734309679871221" />
    </inertial>
    <visual>
      <origin
        xyz="0 0 0"
        rpy="0 0 0" />
      <geometry>
        <mesh
          filename="package://car_sample/meshes/RF_link.STL" />
      </geometry>
      <material
        name="">
        <color
          rgba="0.792156862745098 0.819607843137255 0.933333333333333 1" />
      </material>
    </visual>
    <collision>
      <origin
        xyz="0 0 0"
        rpy="0 0 0" />
      <geometry>
        <mesh
          filename="package://car_sample/meshes/RF_link.STL" />
      </geometry>
    </collision>
  </link>
<gazebo reference="RF_link">
    <material>Gazebo/Black</material>
    <selfCollide>true</selfCollide>
  </gazebo>
  <joint
    name="RF_joint"
    type="continuous">
    <origin
      xyz="0.29328 -0.3725 0.1"
      rpy="0 0 0" />
      <dynamics friction="2"/>
    <parent
      link="base_link" />
    <child
      link="RF_link" />
    <axis
      xyz="0 1 0" />
  </joint>
  <link
    name="RR_link">
    <inertial>
      <origin
        xyz="-1.94289029309402E-16 0.0249999999999999 2.22044604925031E-16"
        rpy="0 0 0" />
      <mass
        value="6.78904509236315" />
      <inertia
        ixx="0.0734309679871222"
        ixy="2.29518052766348E-18"
        ixz="5.19024815104054E-18"
        iyy="0.127548069927643"
        iyz="-1.10751048560327E-17"
        izz="0.0734309679871221" />
    </inertial>
    <visual>
      <origin
        xyz="0 0 0"
        rpy="0 0 0" />
      <geometry>
        <mesh
          filename="package://car_sample/meshes/RR_link.STL" />
      </geometry>
      <material
        name="">
        <color
          rgba="0.792156862745098 0.819607843137255 0.933333333333333 1" />
      </material>
    </visual>
    <collision>
      <origin
        xyz="0 0 0"
        rpy="0 0 0" />
      <geometry>
        <mesh
          filename="package://car_sample/meshes/RR_link.STL" />
      </geometry>
    </collision>
  </link>
<gazebo reference="RR_link">
    <material>Gazebo/Black</material>
    <selfCollide>true</selfCollide>
  </gazebo>
  <joint
    name="RR_joint"
    type="continuous">
    <origin
      xyz="-0.20472 -0.3725 0.1"
      rpy="0 0 0" />
      <dynamics friction="2"/>
    <parent
      link="base_link" />
    <child
      link="RR_link" />
    <axis
      xyz="0 1 0" />
  </joint>
  <link
    name="sensor_link">
    <inertial>
      <origin
        xyz="-0.0131763958667367 -3.07460541276901E-06 -0.131162403073355"
        rpy="0 0 0" />
      <mass
        value="93.7017907857414" />
      <inertia
        ixx="2.05155668597246"
        ixy="-0.000190686516366677"
        ixz="-0.0661121479684105"
        iyy="7.87268899063513"
        iyz="2.91444870280917E-05"
        izz="9.28547608261676" />
    </inertial>

  </link>
  <joint
    name="sensor_joint"
    type="fixed">
    <origin
      xyz="0.044281 0 0.23"
      rpy="0 0 0" />
    <parent
      link="base_link" />
    <child
      link="sensor_link" />
    <axis
      xyz="0 0 0" />
  </joint>
  <gazebo>
   <plugin name="imu_plugin" filename="libgazebo_ros_imu.so">
        <alwaysOn>true</alwaysOn>
        <bodyName>base_footprint_link</bodyName>
        <topicName>imu_data</topicName>
        <serviceName>imu_service</serviceName>
        <gaussianNoise>0.0</gaussianNoise>
        <updateRate>20.0</updateRate>
      </plugin>
    </gazebo>
<gazebo>
  <plugin name="skid_steer_drive_controller" filename="libgazebo_ros_skid_steer_drive.so">
    <updateRate>100.0</updateRate>
    <robotNamespace>/</robotNamespace>
    <leftFrontJoint>LF_joint</leftFrontJoint>
    <rightFrontJoint>RF_joint</rightFrontJoint>
    <leftRearJoint>LR_joint</leftRearJoint>
    <rightRearJoint>RR_joint</rightRearJoint>
    <wheelSeparation>0.4</wheelSeparation>
    <wheelDiameter>0.330</wheelDiameter>
    <robotBaseFrame>base_link</robotBaseFrame>
    <torque>20</torque>
    <topicName>cmd_vel</topicName>
    <broadcastTF>false</broadcastTF>
    <odometryTopic>odom</odometryTopic>
    <odometryFrame>base_link</odometryFrame>
  </plugin>
</gazebo>

</robot>
